Workbook

Sheet Esto
A1: Código | B1: Nome do Perfume | C1: Categoria | D1: Inicio | E1: Vendido | F1: Total | G1: Coluna1
A2: B00001 | B2: Brz Blossom | C2: BODYSPLASH | D2: 11 | E2: =SUMIF(Vm!$C:$C,$A2,Vm!$F:$F) -> 2 | F2: =SUM(D2-E2) -> 9 | G2: OK | I2: total | J2: Inicio | K2: Vendida | L2: Atual
A3: B00002 | B3: Nectar Crystal | C3: BODYSPLASH | D3: 16 | E3: =SUMIF(Vm!$C:$C,$A3,Vm!$F:$F) -> 3 | F3: =SUM(D3-E3) -> 13 | G3: OK | I3: bodysplah | J3: =SUM(#REF!) -> #REF! | K3: =SUM(E2:E6) -> 14 | L3: =SUM(F2:F6) -> 51
A4: B00003 | B4: Rubi | C4: BODYSPLASH | D4: 15 | E4: =SUMIF(Vm!$C:$C,$A4,Vm!$F:$F) -> 1 | F4: =SUM(D4-E4) -> 14 | G4: OK | I4: 10ml | J4: =SUM(#REF!) -> #REF! | K4: =SUM(E9:E73) -> 55 | L4: =SUM(F9:F73) -> 375
A5: B00004 | B5: Silver Z | C5: BODYSPLASH | D5: 12 | E5: =SUMIF(Vm!$C:$C,$A5,Vm!$F:$F) -> 4 | F5: =SUM(D5-E5) -> 8 | G5: OK | I5: 28ml | J5: =SUM(#REF!) -> #REF! | K5: =SUM(E80:E142) -> 296 | L5: =SUM(F80:F142) -> 1057
A6: B00005 | B6: Sunshine | C6: BODYSPLASH | D6: 11 | E6: =SUMIF(Vm!$C:$C,$A6,Vm!$F:$F) -> 4 | F6: =SUM(D6-E6) -> 7 | G6: OK | I6: 50ml | J6: =SUM(#REF!) -> #REF! | K6: =SUM( E149:E150) -> 6 | L6: =SUM( F149:F150) -> 31
I7: 100ml | J7: =SUM(#REF!) -> #REF! | K7: =SUM(E153:E211) -> 56 | L7: =SUM(F153:F211) -> 280
A8: Código | B8: Nome do Perfume | C8: Categoria | D8: Inicio | E8: Vendido | F8: Total | G8: Coluna1 | I8: hidratante | J8: =SUM(#REF!) -> #REF! | K8: =SUM(E217:E241) -> 24 | L8: =SUM(F217:F241) -> 275
A9: P01003 | B9: 2 Love - 10 Ml | C9: 10ML | D9: 5 | E9: =SUMIF(Vm!$C:$C,$A9,Vm!$F:$F) -> 0 | F9: =SUM(D9-E9) -> 5 | G9: ok
A10: P01030 | B10: Ahazzo - 10 Ml | C10: 10ML | D10: 5 | E10: =SUMIF(Vm!$C:$C,$A10,Vm!$F:$F) -> 2 | F10: =SUM(D10-E10) -> 3 | G10: ok
A11: P01031 | B11: Animalz - 10 Ml | C11: 10ML | D11: 8 | E11: =SUMIF(Vm!$C:$C,$A11,Vm!$F:$F) -> 1 | F11: =SUM(D11-E11) -> 7 | G11: ok
A12: P01063 | B12: Aurarose-10Ml | C12: 10ML | D12: 7 | E12: =SUMIF(Vm!$C:$C,$A12,Vm!$F:$F) -> 0 | F12: =SUM(D12-E12) -> 7 | G12: ok
A13: P01001 | B13: Autêntica - 10 Ml | C13: 10ML | D13: 9 | E13: =SUMIF(Vm!$C:$C,$A13,Vm!$F:$F) -> 0 | F13: =SUM(D13-E13) -> 9 | G13: ok
A14: P01004 | B14: Beauty - 10 Ml | C14: 10ML | D14: 4 | E14: =SUMIF(Vm!$C:$C,$A14,Vm!$F:$F) -> 0 | F14: =SUM(D14-E14) -> 4 | G14: ok
A15: P01032 | B15: Black Horse - 10 Ml | C15: 10ML | D15: 6 | E15: =SUMIF(Vm!$C:$C,$A15,Vm!$F:$F) -> 0 | F15: =SUM(D15-E15) -> 6 | G15: ok
A16: P01033 | B16: Blue De Zyone - 10 Ml | C16: 10ML | D16: 7 | E16: =SUMIF(Vm!$C:$C,$A16,Vm!$F:$F) -> 2 | F16: =SUM(D16-E16) -> 5 | G16: ok
A17: P01034 | B17: Boss Man - 10 Ml | C17: 10ML | D17: 7 | E17: =SUMIF(Vm!$C:$C,$A17,Vm!$F:$F) -> 2 | F17: =SUM(D17-E17) -> 5 | G17: ok
A18: P01035 | B18: Bravus - 10 Ml | C18: 10ML | D18: 7 | E18: =SUMIF(Vm!$C:$C,$A18,Vm!$F:$F) -> 0 | F18: =SUM(D18-E18) -> 7 | G18: ok
A19: P01005 | B19: Brz Blossom -10 Ml | C19: 10ML | D19: 7 | E19: =SUMIF(Vm!$C:$C,$A19,Vm!$F:$F) -> 3 | F19: =SUM(D19-E19) -> 4 | G19: ok
A20: P01036 | B20: Brz Dark - 10 Ml | C20: 10ML | D20: 6 | E20: =SUMIF(Vm!$C:$C,$A20,Vm!$F:$F) -> 2 | F20: =SUM(D20-E20) -> 4 | G20: ok
... A77: P01060 | B77: Zayan - 10 Ml | C77: 10ML | D77: 16 | E77: =SUMIF(Vm!$C:$C,$A77,Vm!$F:$F) -> 3 | F77: =SUM(D77-E77) -> 13 | G77: ok
A79: Código | B79: Nome do Perfume | C79: Categoria | D79: Inicio | E79: Vendido | F79: Total | G79: Coluna2 | H79: Coluna3
A80: P02803 | B80: 2 Love - 28 Ml | C80: 28ML | D80: 9 | E80: =SUMIF(Vm!$C:$C,$A80,Vm!$F:$F) -> 0 | F80: =SUM(D80-E80) -> 9 | G80: ok | H80: 46093
A81: P02800 | B81: Aurarose- 28 Ml | C81: 28ML | D81: 47 | E81: =SUMIF(Vm!$C:$C,$A81,Vm!$F:$F) -> 4 | F81: =SUM(D81-E81) -> 43 | G81: ok | J81: 9
A82: P02801 | B82: Autêntica - 28 Ml | C82: 28ML | D82: 9 | E82: =SUMIF(Vm!$C:$C,$A82,Vm!$F:$F) -> 1 | F82: =SUM(D82-E82) -> 8 | G82: ok
A83: P02804 | B83: Beauty - 28 Ml | C83: 28ML | D83: 5 | E83: =SUMIF(Vm!$C:$C,$A83,Vm!$F:$F) -> 0 | F83: =SUM(D83-E83) -> 5 | G83: ok
A84: P02805 | B84: Brz Blossom- 28 Ml | C84: 28ML | D84: 59 | E84: =SUMIF(Vm!$C:$C,$A84,Vm!$F:$F) -> 13 | F84: =SUM(D84-E84) -> 46 | G84: ok
A85: P02806 | B85: Brz Intense Woman- 28 Ml | C85: 28ML | D85: 11 | E85: =SUMIF(Vm!$C:$C,$A85,Vm!$F:$F) -> 1 | F85: =SUM(D85-E85) -> 10 | G85: ok
A86: P02825 | B86: Brz Woman - 28 Ml | C86: 28ML | D86: 15 | E86: =SUMIF(Vm!$C:$C,$A86,Vm!$F:$F) -> 4 | F86: =SUM(D86-E86) -> 11 | G86: ok
A87: P02807 | B87: Cintilante - 28 Ml | C87: 28ML | D87: 7 | E87: =SUMIF(Vm!$C:$C,$A87,Vm!$F:$F) -> 1 | F87: =SUM(D87-E87) -> 6 | G87: ok
A88: P02808 | B88: Creta - 28 Ml | C88: 28ML | D88: 29 | E88: =SUMIF(Vm!$C:$C,$A88,Vm!$F:$F) -> 1 | F88: =SUM(D88-E88) -> 28 | G88: ok
A89: P02857 | B89: Dunes - 28 Ml | C89: 28ML | D89: 7 | E89: =SUMIF(Vm!$C:$C,$A89,Vm!$F:$F) -> 4 | F89: =SUM(D89-E89) -> 3 | G89: ok
A90: P02809 | B90: Five Z - 28 Ml | C90: 28ML | D90: 10 | E90: =SUMIF(Vm!$C:$C,$A90,Vm!$F:$F) -> 0 | F90: =SUM(D90-E90) -> 10 | G90: ok
A91: P02802 | B91: Glow - 28 Ml | C91: 28ML | D91: 34 | E91: =SUMIF(Vm!$C:$C,$A91,Vm!$F:$F) -> 8 | F91: =SUM(D91-E91) -> 26 | G91: ok
A92: P02810 | B92: Gold Woman - 28 Ml | C92: 28ML | D92: 11 | E92: =SUMIF(Vm!$C:$C,$A92,Vm!$F:$F) -> 1 | F92: =SUM(D92-E92) -> 10 | G92: ok
A93: P02811 | B93: Gs - 28 Ml | C93: 28ML | D93: 7 | E93: =SUMIF(Vm!$C:$C,$A93,Vm!$F:$F) -> 0 | F93: =SUM(D93-E93) -> 7 | G93: ok
... A124: P02838 | B124: Brz Intense Men - 28 Ml | C124: 28ML | D124: 9 | E124: =SUMIF(Vm!$C:$C,$A124,Vm!$F:$F) -> 0 | F124: =SUM(D124-E124) -> 9 | G124: ok
A125: P02839 | B125: Brz Men - 28 Ml | C125: 28ML | D125: 29 | E125: =SUMIF(Vm!$C:$C,$A125,Vm!$F:$F) -> 3 | F125: =SUM(D125-E125) -> 26 | G125: -1
A126: P02840 | B126: Brz Urban - 28 Ml | C126: 28ML | D126: 9 | E126: =SUMIF(Vm!$C:$C,$A126,Vm!$F:$F) -> 2 | F126: =SUM(D126-E126) -> 7 | G126: ok
A127: P02841 | B127: Champion - 28 Ml | C127: 28ML | D127: 37 | E127: =SUMIF(Vm!$C:$C,$A127,Vm!$F:$F) -> 2 | F127: =SUM(D127-E127) -> 35 | G127: ok
...

Sheet Vm
A1: Mês/Ano | B1: Nome | C1: Código | D1: Nome do Perfume | E1: Produto | F1: Quantidade Vendida | G1: Valor de custo/ empresa | H1: Valor Unitário | I1: Valor Total da Venda | J1: Situação
A2: 46082 | B2: Junin ( Paulo Cesar) | C2: P02819 | D2: Miss - Perfume 28 Ml | E2: 28ML | F2: 1
A3: 46082 | B3: Matheus Rici | C3: P02851 | D3: Silver Z - 28 Ml | E3: 28ML | F3: 1 | J3: Pago
A4: 46082 | B4: Junin ( Paulo Cesar) | C4: B00005 | D4: Sunshine | E4: BODYSPLASH | F4: 1 | J4: Pago
A5: 46083 | B5: Alberto Henrique | C5: P10005 | D5: Luminous Flowers - Perfume 100 Ml | E5: 100ML | F5: 1 | J5: Pago
A6: 46083 | B6: Alberto Henrique | C6: P10013 | D6: Brz Woman (121 Woman Brz) - Perfume 100 Ml | E6: 100ML | F6: 1 | J6: Pago
A7: 46083 | B7: Alberto Henrique | C7: P10038 | D7: Boss Man - Perfume 100 ML | E7: 100ML | F7: 1 | J7: Pago
A8: 46083 | B8: Neiz Vidal | C8: P01005 | D8: Brz Blossom -10 Ml | E8: 10ML | F8: 1
A9: 46083 | B9: Neiz Vidal | C9: P01053 | D9: Malirah - 10 Ml | E9: 10ML | F9: 1
A10: 46083 | B10: Neiz Vidal | C10: P01030 | D10: Ahazzo - 10 Ml | E10: 10ML | F10: 1
A11: 46083 | B11: Neiz Vidal | C11: P01034 | D11: Boss Man - 10 Ml | E11: 10ML | F11: 1
A12: 46083 | B12: Neiz Vidal | C12: P01033 | D12: Blue De Zyone - 10 Ml | E12: 10ML | F12: 1
A13: 46083 | B13: Neiz Vidal | C13: P01036 | D13: Brz Dark - 10 Ml | E13: 10ML | F13: 1
A14: 46083 | B14: Neiz Vidal | C14: P01039 | D14: Champion - 10 Ml | E14: 10ML | F14: 1
A15: 46083 | B15: Neiz Vidal | C15: P01040 | D15: Charmy - 10 Ml | E15: 10ML | F15: 1
A16: 46083 | B16: Neiz Vidal | C16: P01049 | D16: Selvagem - 10 Ml | E16: 10ML | F16: 1
A17: 46083 | B17: Neiz Vidal | C17: P01050 | D17: Silver Z - 10 Ml | E17: 10ML | F17: 1
A18: 46083 | B18: Neiz Vidal | C18: P01055 | D18: Sharif - 10 Ml | E18: 10ML | F18: 1
A19: 46083 | B19: Neiz Vidal | C19: P01060 | D19: Zayan - 10 Ml | E19: 10ML | F19: 1
... A27: 46083 | B27: Neiz Vidal | C27: P01058 | D27: Rubi - 10 Ml | E27: 10ML | F27: 1
A28: 46083 | B28: Alberto Henrique | C28: P02851 | D28: Silver Z - Perfume 28 Ml | E28: 28ML | F28: 1 | J28: Pago
A29: 46083 | B29: Junin ( Paulo Cesar) | C29: P02815 | D29: Luminous Flowers - 28 Ml | E29: 28ML | F29: 1
A30: 46083 | B30: Leo Souza | C30: P02822 | D30: Sweet Blue - 28 Ml | E30: 28ML | F30: 1 | J30: Pago
A31: 46083 | B31: Leo Souza | C31: P02824 | D31: Tuberose Shine - 28 Ml | E31: 28ML | F31: 1 | J31: Pago
A32: 46083 | B32: Yuri Origem | C32: P02816 | D32: Luminous Girl (Nice Girl) - Perfume 28 Ml | E32: 28ML | F32: 1 | J32: Pago
A33: 46083 | B33: Yuri Origem | C33: P02850 | D33: Selvagem - Perfume 28 Ml | E33: 28ML | F33: 1 | J33: Pago
A34: 46084 | B34: Junin ( Paulo Cesar) | C34: P10012 | D34: Brz Blossom - 100 Ml | E34: 100ML | F34: 1 | J34: Pago
A35: 46084 | B35: Luciano | C35: P10046 | D35: Code Man - 100 M | E35: 100ML | F35: 1
A36: 46084 | B36: Luciano | C36: P10036 | D36: Black Horse - 100 Ml | E36: 100ML | F36: 1
A37: 46084 | B37: Luciano | C37: P10020 | D37: Luminous Girl - 100 Ml | E37: 100ML | F37: 1
A38: 46084 | B38: Luciano | C38: P10015 | D38: Creta - 100 Ml | E38: 100ML | F38: 1
A39: 46084 | B39: Luciano | C39: P10050 | D39: Selvagem - 100 Ml | E39: 100ML | F39: 2
A40: 46084 | B40: Matheus Rici | C40: P10034 | D40: Ahazzo - 100 Ml | E40: 100ML | F40: 1 | J40: Pago
A41: 46084 | B41: Pedrão | C41: P10038 | D41: Boss Man - 100 ML | E41: 100ML | F41: 1 | J41: Pago
A42: 46084 | B42: Thiago Cotuba | C42: P10018 | D42: La Vie Est Amour - 100 Ml | E42: 100ML | F42: 1 | J42: Pago
A43: 46084 | B43: Junin ( Paulo Cesar) | C43: P02829 | D43: Personal Z - 28 Ml | E43: 28ML | F43: 1
A44: 46084 | B44: Luciano | C44: P02825 | D44: Brz Woman - 28 Ml | E44: 28ML | F44: 1
A45: 46084 | B45: Luciano | C45: P02850 | D45: Selvagem - 28 Ml | E45: 28ML | F45: 1
A46: 46084 | B46: Mayra | C46: P02802 | D46: Glow - 28 Ml | E46: 28ML | F46: 1
A47: 46084 | B47: Tauan | C47: P02815 | D47: Luminous Flowers - 28 Ml | E47: 28ML | F47: 2 | J47: Pago
...

Sheet Resumo 
A1: Total pago | B1: Total devendo
A2: =SUM(J4:J1002)*-1 -> 0 | B2: =SUM(C5:C97) -> 0
A4: Mês/Ano | B4: Vendedor | C4: Total Vendido (R$) | D4: 10ML | E4: 28ML | F4: 50ML | G4: 100ML | H4: Hidratante | I4: Bodysplash | J4: Total | K4: Pagamento | L4: OBSERVAÇÃO
A5: fev | B5: Eduardo-jan ( 5.000,00)
A6: fev | B6: Felipe Araujo- jan/dez
A7: fev | B7: Felipe Santos-fev
A8: fev | B8: Igor Paes- fev
A9: fev | B9: Isabela Leal- jan
A10: fev | B10: Junin (Paulo Cesar)- fev
A11: fev | B11: Junin (Paulo Cesar)-jan
A12: fev | B12: Leonardo celico-fev
A13: fev | B13: Luciano-fev
A14: fev | B14: Thamiris Bambini-fev
A15: 46091 | B15: Luis Fernando ( energia solar)
A16: 46090 | B16: Isabela Leal
A17: 46088 | B17: Flavio ( queijin)
A18: 46087 | B18: Igor Paes
A19: 46086 | B19: Felipe Santos
A20: 46084 | B20: Luciano
A21: 46084 | B21: Neiz Vidal
A22: 46084 | B22: Pedrão
A23: 46083 | B23: Yuri Origem
A24: 46082 | B24: Junin ( Paulo Cesar)
A25: 46054 | B25: Jonatha sandoval- fev
A26: 46093 | B26: Jonathan Sandoval
... A28: 46084 | B28: Tauan
A29: fev | B29: Eidy-fev
A30: fev | B30: Felipe Araujo-fev
A31: fev | B31: Flavio ( queijin)- jan
A32: fev | B32: Isa Mulher do Thiago- fev
A33: fev | B33: João Previato -fev
A34: fev | B34: Pedrão-fev
A35: 414978 | B35: Alberto Henrique
A36: 46092 | B36: Isa do Thiago
A37: 46092 | B37: Paulo Gouveia
A38: 46091 | B38: Livia Barbosa
A39: 46090 | B39: Alex Rocket League
A40: 46090 | B40: Pedro V.l
A41: 46089 | B41: Arthur Pini
A42: 46089 | B42: Thais Rodrigues
...

Sheet Fin
A1: GANHOU ESSE MÊS + DIVIDAS PAGAS | F1: Matheus Rici Lucro | G1: Custo | H1: Total
A2: Ganho Total | F2: =SUM('M Rici vend '!J2:J1000) -> 0 | G2: =SUM('M Rici vend '!H2:H1000) -> 0 | H2: =SUM(F2-G2) -> 0
A3: =SUM('Resumo '!A2) -> 0
A5: GANHO MENSAL + DIVIDA
A6: =SUM('Resumo '!A2:B2) -> 0
A8: DIVIDA devendo
A9: =SUM('Resumo '!B2) -> 0
A11: Ganho mensal
A14: Ganho sem vp
A15: =SUM(A12-F2) -> 0

Sheet M Rici vend 
A1: Data | B1: Cliente | C1: Nascimento | D1: Telefone | E1: Nome | G1: Quantidade | H1: Custo | I1: Valor | J1: lucro | K1: Valor Total
